Workbook

Sheet Zbiorcza
B2: GDAŃSK/POWIAT GDAŃSKI/WOJEWÓDZTWO POMORSKIE | AF2: GDAŃSK/POWIAT GDAŃSKI/WOJEWÓDZTWO POMORSKIE | AG2: GDAŃSK/POWIAT GDAŃSKI/WOJEWÓDZTWO POMORSKIE
B3: Kwartał | C3: Ceny transakcyjne - ogółem - powiat gdański | D3: Ceny transakcyjne - rynek wtórny - powiat gdański | E3: Ceny transakcyjne - rynek pierwotny - powiat gdański | F3: Ceny transakcyjne - rynek wtórny - Gdańsk | G3: Ceny transakcyjne - rynek pierwotny - Gdańsk | I3: Ceny transakcyjne do 40 - powiat gdański | J3: Ceny transakcyjne 40-60 - powiat gdański | K3: Ceny transakcyjne 60-80 - powiat gdański | L3: Ceny transakcyjne powyżej 80 - powiat gdański | M3: Ceny transakcyjne do 35 - Gdańsk | N3: Ceny transakcyjne 35-40 - Gdańsk | O3: Ceny transakcyjne 40-50 - Gdańsk | Q3: Ceny transakcyjne 50-60 - Gdańsk | R3: Ceny transakcyjne 60-70 - Gdańsk | S3: Ceny transakcyjne 70-80 - Gdańsk | U3: Ceny transakcyjne 80-100 - Gdańsk | V3: Ceny transakcyjne powyżej 100 - Gdańsk | X3: Wskaźnik cen towarów i usług konsumpcyjnych - województwo pomorskie - ogółem - okres poprzedni = 100 | Y3: Wskaźnik inflacji [miesiąc poprzedni =1] łańcuchowy | AA3: Stopa bezrobocia - powiat gdański | AB3: Mieszkania oddane do użytkowania - powiat gdański | AC3: Przeciętn wynagrodzenia brutto - województwo pomorskie | AD3: Przyrost naturalny - powiat gdański | AF3: do modelu statycznego | AP3: do modelu dynamicznego
B4: Kw | C4: Cena_p | D4: Cena_wt_p | E4: Cena_pierw_p | F4: Cena_wt_m | G4: Cena_pierw_m | H4: Cena_mean | I4: Cena_do40_p | J4: Cena_40-60_p | K4: Cena_60-80_p | L4: Cena_pow80_p | M4: Cena_do 35_m | N4: Cena_35-40_m | O4: Cena_40-50_m | P4: Cena_35-50_mean | Q4: Cena_50-60_m | R4: Cena_60-70_m | S4: Cena_70-80_m | T4: Cena_50-80_mean | U4: Cena_80-100_m | V4: Cena_pow100_m | W4: Cena_pow80_mean | X4: Wsk_cen_w | Y4: Wsk_cen_lancuch | Z4: Wsk_cen_jednopod | AA4: Bezr_p | AB4: M_p | AC4: W_w | AD4: PN_p | AF4: Kw | AG4: Cena | AH4: M_do35 | AI4: M_35-50 | AJ4: M_50-80 | AK4: Wsk_cen | AL4: Bezr | AM4: W | AN4: cena-1 | AP4: Kw | AQ4: Cena | AR4: M_do35 | AS4: M_35-50 | AT4: M_50-80 | AU4: Wsk_cen | AV4: Bezr | AW4: W | AX4: cena-1
B5: I 2015 | C5: 4086 | D5: 3819 | E5: 4324 | F5: 5166.4163 | G5: 5950.9242 | H5: =AVERAGE(F5,G5) -> 5558.6702 | I5: 4161 | J5: 4031 | K5: 4081 | L5: 4267 | M5: 5730.95 | N5: 5254.28 | O5: 5601.99 | P5: =AVERAGE(N5,O5) -> 5428.135 | Q5: 5446.37 | R5: 5334.82 | S5: 5680.86 | T5: =AVERAGE(Q5,R5,S5) -> 5487.35 | U5: 6094.91 | V5: 5999.68 | W5: =AVERAGE(U5,V5) -> 6047.295 | X5: 99.6 | Y5: =X5/100 -> 0.996 | Z5: 100 | AA5: 5.7333333 | AB5: 272 | AC5: 4376.77 | AF5: I 2015 | AG5: 5730.95 | AH5: 1 | AI5: 0 | AJ5: 0 | AK5: 100 | AL5: 5.7333333 | AM5: 4376.77 | AP5: II 2015 | AQ5: 5695.75 | AR5: 1 | AS5: 0 | AT5: 0 | AU5: 100.6 | AV5: 5.3333333 | AW5: 4128.89 | AX5: 5730.95
B6: II 2015 | C6: 3992 | D6: 3639 | E6: 4192 | F6: 5112.696 | G6: 5749.0184 | H6: =AVERAGE(F6,G6) -> 5430.8572 | I6: 4212 | J6: 3991 | K6: 3864 | L6: 4018 | M6: 5695.75 | N6: 5035.23 | O6: 5662.51 | P6: =AVERAGE(N6,O6) -> 5348.87 | Q6: 5322.06 | R6: 5471.47 | S6: 5676.65 | T6: =AVERAGE(Q6,R6,S6) -> 5490.06 | U6: 5650.04 | V6: 5799.38 | W6: =AVERAGE(U6,V6) -> 5724.71 | X6: 100.6 | Y6: =X6/100 -> 1.006 | Z6: =Y6*Z5 -> 100.6 | AA6: 5.3333333 | AB6: 182 | AC6: 4128.89 | AD6: -209 | AF6: II 2015 | AG6: 5695.75 | AH6: 1 | AI6: 0 | AJ6: 0 | AK6: 100.6 | AL6: 5.3333333 | AM6: 4128.89 | AN6: 5730.95 | AP6: III 2015 | AQ6: 5617.39 | AR6: 1 | AS6: 0 | AT6: 0 | AU6: 100.1976 | AV6: 4.6666667 | AW6: 4193.17 | AX6: 5695.75
B7: III 2015 | C7: 4059 | D7: 3720 | E7: 4181 | F7: 5114 | G7: 6089.0239 | H7: =AVERAGE(F7,G7) -> 5601.512 | I7: 4223 | J7: 4126 | K7: 3765 | L7: 3982 | M7: 5617.39 | N7: 5329.61 | O7: 5697.62 | P7: =AVERAGE(N7,O7) -> 5513.615 | Q7: 5413.42 | R7: 5437.46 | S7: 5477.16 | T7: =AVERAGE(Q7,R7,S7) -> 5442.68 | U7: 5836.22 | V7: 5517.04 | W7: =AVERAGE(U7,V7) -> 5676.63 | X7: 99.6 | Y7: =X7/100 -> 0.996 | Z7: =Y7*Z6 -> 100.1976 | AA7: 4.6666667 | AB7: 279 | AC7: 4193.17 | AF7: III 2015 | AG7: 5617.39 | AH7: 1 | AI7: 0 | AJ7: 0 | AK7: 100.1976 | AL7: 4.6666667 | AM7: 4193.17 | AN7: 5695.75 | AP7: IV 2015 | AQ7: 5564.01 | AR7: 1 | AS7: 0 | AT7: 0 | AU7: 100.0974 | AV7: 4.2 | AW7: 4350 | AX7: 5617.39
B8: IV 2015 | C8: 3890 | D8: 3328 | E8: 4188 | F8: 5441.34 | G8: 6030.8631 | H8: =AVERAGE(F8,G8) -> 5736.1015 | I8: 4079 | J8: 3863 | K8: 4004 | L8: 0 | M8: 5564.01 | N8: 5356.53 | O8: 5547.46 | P8: =AVERAGE(N8,O8) -> 5451.995 | Q8: 5391.1 | R8: 5398.41 | S8: 5460.22 | T8: =AVERAGE(Q8,R8,S8) -> 5416.5767 | U8: 5615.54 | V8: 5156.17 | W8: =AVERAGE(U8,V8) -> 5385.855 | X8: 99.9 | Y8: =X8/100 -> 0.999 | Z8: =Y8*Z7 -> 100.0974 | AA8: 4.2 | AB8: 496 | AC8: 4350 | AD8: 49 | AF8: IV 2015 | AG8: 5564.01 | AH8: 1 | AI8: 0 | AJ8: 0 | AK8: 100.0974 | AL8: 4.2 | AM8: 4350 | AN8: 5617.39 | AP8: I 2016 | AQ8: 5413.68 | AR8: 1 | AS8: 0 | AT8: 0 | AU8: 99.496818 | AV8: 4.1666667 | AW8: 4491.63 | AX8: 5564.01
B9: I 2016 | C9: 4052 | D9: 3616 | E9: 4384 | F9: 5364 | G9: 6451.94 | H9: =AVERAGE(F9,G9) -> 5907.97 | I9: 4232 | J9: 4120 | K9: 4246 | L9: 3370 | M9: 5413.68 | N9: 5213.76 | O9: 5581.68 | P9: =AVERAGE(N9,O9) -> 5397.72 | Q9: 5328.77 | R9: 5284.9 | S9: 5395.04 | T9: =AVERAGE(Q9,R9,S9) -> 5336.2367 | U9: 5649.45 | V9: 5191.97 | W9: =AVERAGE(U9,V9) -> 5420.71 | X9: 99.4 | Y9: =X9/100 -> 0.994 | Z9: =Y9*Z8 -> 99.496818 | AA9: 4.1666667 | AB9: 326 | AC9: 4491.63 | AF9: I 2016 | AG9: 5413.68 | AH9: 1 | AI9: 0 | AJ9: 0 | AK9: 99.496818 | AL9: 4.1666667 | AM9: 4491.63 | AN9: 5564.01 | AP9: II 2016 | AQ9: 5517.48 | AR9: 1 | AS9: 0 | AT9: 0 | AU9: 100.0938 | AV9: 3.8333333 | AW9: 4333.06 | AX9: 5413.68
B10: II 2016 | C10: 4202 | D10: 3798 | E10: 4474 | F10: 5521 | G10: 6185.233 | H10: =AVERAGE(F10,G10) -> 5853.1165 | I10: 4393 | J10: 4319 | K10: 4165 | L10: 3608 | M10: 5517.48 | N10: 5253.76 | O10: 5460 | P10: =AVERAGE(N10,O10) -> 5356.88 | Q10: 5269.11 | R10: 5179.79 | S10: 5297.82 | T10: =AVERAGE(Q10,R10,S10) -> 5248.9067 | U10: 5453.66 | V10: 5334.68 | W10: =AVERAGE(U10,V10) -> 5394.17 | X10: 100.6 | Y10: =X10/100 -> 1.006 | Z10: =Y10*Z9 -> 100.0938 | AA10: 3.8333333 | AB10: 95 | AC10: 4333.06 | AD10: 255 | AF10: II 2016 | AG10: 5517.48 | AH10: 1 | AI10: 0 | AJ10: 0 | AK10: 100.0938 | AL10: 3.8333333 | AM10: 4333.06 | AN10: 5413.68 | AP10: III 2016 | AQ10: 5688.82 | AR10: 1 | AS10: 0 | AT10: 0 | AU10: 99.993705 | AV10: 3.7333333 | AW10: 4352.28 | AX10: 5517.48
B11: III 2016 | C11: 4075 | D11: 3952 | E11: 4412 | F11: 5555.35 | G11: 6283.4649 | H11: =AVERAGE(F11,G11) -> 5919.4074 | I11: 4139 | J11: 3972 | K11: 3976 | L11: 4800 | M11: 5688.82 | N11: 5374.74 | O11: 5528.42 | P11: =AVERAGE(N11,O11) -> 5451.58 | Q11: 5390.76 | R11: 5306.51 | S11: 5429.27 | T11: =AVERAGE(Q11,R11,S11) -> 5375.5133 | U11: 5616.49 | V11: 5465.36 | W11: =AVERAGE(U11,V11) -> 5540.925 | X11: 99.9 | Y11: =X11/100 -> 0.999 | Z11: =Y11*Z10 -> 99.993705 | AA11: 3.7333333 | AB11: 263 | AC11: 4352.28 | AF11: III 2016 | AG11: 5688.82 | AH11: 1 | AI11: 0 | AJ11: 0 | AK11: 99.993705 | AL11: 3.7333333 | AM11: 4352.28 | AN11: 5517.48 | AP11: IV 2016 | AQ11: 5725.84 | AR11: 1 | AS11: 0 | AT11: 0 | AU11: 100.69366 | AV11: 3.6333333 | AW11: 4467.88 | AX11: 5688.82
B12: IV 2016 | C12: 3941 | D12: 3926 | E12: 4151 | F12: 5609.67 | G12: 6481.1886 | H12: =AVERAGE(F12,G12) -> 6045.4293 | I12: 4027 | J12: 3842 | K12: 4167 | L12: 3629 | M12: 5725.84 | N12: 5598.45 | O12: 5616.83 | P12: =AVERAGE(N12,O12) -> 5607.64 | Q12: 5553.41 | R12: 5423.2 | S12: 5535.54 | T12: =AVERAGE(Q12,R12,S12) -> 5504.05 | U12: 5703.95 | V12: 5637.03 | W12: =AVERAGE(U12,V12) -> 5670.49 | X12: 100.7 | Y12: =X12/100 -> 1.007 | Z12: =Y12*Z11 -> 100.69366 | AA12: 3.6333333 | AB12: 211 | AC12: 4467.88 | AD12: 667 | AF12: IV 2016 | AG12: 5725.84 | AH12: 1 | AI12: 0 | AJ12: 0 | AK12: 100.69366 | AL12: 3.6333333 | AM12: 4467.88 | AN12: 5688.82 | AP12: I 2017 | AQ12: 6043.25 | AR12: 1 | AS12: 0 | AT12: 0 | AU12: 101.7006 | AV12: 3.6 | AW12: 4697.92 | AX12: 5725.84
B13: I 2017 | C13: 4197 | D13: 3958 | E13: 4341 | F13: 5778.4937 | G13: 6430.394 | H13: =AVERAGE(F13,G13) -> 6104.4439 | I13: 4531 | J13: 4293 | K13: 4090 | L13: 3494 | M13: 6043.25 | N13: 5793.44 | O13: 5757.72 | P13: =AVERAGE(N13,O13) -> 5775.58 | Q13: 5754.51 | R13: 5566.31 | S13: 5729.77 | T13: =AVERAGE(Q13,R13,S13) -> 5683.53 | U13: 5756.43 | V13: 5955.3 | W13: =AVERAGE(U13,V13) -> 5855.865 | X13: 101 | Y13: =X13/100 -> 1.01 | Z13: =Y13*Z12 -> 101.7006 | AA13: 3.6 | AB13: 273 | AC13: 4697.92 | AF13: I 2017 | AG13: 6043.25 | AH13: 1 | AI13: 0 | AJ13: 0 | AK13: 101.7006 | AL13: 3.6 | AM13: 4697.92 | AN13: 5725.84 | AP13: II 2017 | AQ13: 6283.44 | AR13: 1 | AS13: 0 | AT13: 0 | AU13: 102.1074 | AV13: 3.4 | AW13: 4501.59 | AX13: 6043.25
B14: II 2017 | C14: 4197 | D14: 4066 | E14: 4423 | F14: 6030.4699 | G14: 6500.6278 | H14: =AVERAGE(F14,G14) -> 6265.5489 | I14: 4584 | J14: 4356 | K14: 4217 | L14: 3640 | M14: 6283.44 | N14: 5864.524 | O14: 5958.362 | P14: =AVERAGE(N14,O14) -> 5911.443 | Q14: 5833.177 | R14: 5738.95 | S14: 6044.579 | T14: =AVERAGE(Q14,R14,S14) -> 5872.2353 | U14: 5677.823 | V14: 5701.641 | W14: =AVERAGE(U14,V14) -> 5689.732 | X14: 100.4 | Y14: =X14/100 -> 1.004 | Z14: =Y14*Z13 -> 102.1074 | AA14: 3.4 | AB14: 246 | AC14: 4501.59 | AD14: 161 | AF14: II 2017 | AG14: 6283.44 | AH14: 1 | AI14: 0 | AJ14: 0 | AK14: 102.1074 | AL14: 3.4 | AM14: 4501.59 | AN14: 6043.25 | AP14: III 2017 | AQ14: 6574.007 | AR14: 1 | AS14: 0 | AT14: 0 | AU14: 101.90319 | AV14: 3.2666667 | AW14: 4544.14 | AX14: 6283.44
B15: III 2017 | C15: 4080 | D15: 4015 | E15: 4200 | F15: 6065.28 | G15: 6816.261 | H15: =AVERAGE(F15,G15) -> 6440.7705 | I15: 4849 | J15: 4307 | K15: 4143 | L15: 3581 | M15: 6574.007 | N15: 5910.496 | O15: 6244.027 | P15: =AVERAGE(N15,O15) -> 6077.2615 | Q15: 5997.943 | R15: 5995.003 | S15: 6219.478 | T15: =AVERAGE(Q15,R15,S15) -> 6070.808 | U15: 5856.793 | V15: 5624.107 | W15: =AVERAGE(U15,V15) -> 5740.45 | X15: 99.8 | Y15: =X15/100 -> 0.998 | Z15: =Y15*Z14 -> 101.90319 | AA15: 3.2666667 | AB15: 527 | AC15: 4544.14 | AF15: III 2017 | AG15: 6574.007 | AH15: 1 | AI15: 0 | AJ15: 0 | AK15: 101.90319 | AL15: 3.2666667 | AM15: 4544.14 | AN15: 6283.44 | AP15: IV 2017 | AQ15: 6713.74 | AR15: 1 | AS15: 0 | AT15: 0 | AU15: 102.92222 | AV15: 2.9 | AW15: 4779.32 | AX15: 6574.007
B16: IV 2017 | C16: 4237 | D16: 4245 | E16: 4223 | F16: 6337.1235 | G16: 6829.488 | H16: =AVERAGE(F16,G16) -> 6583.3057 | I16: 4615 | J16: 4305 | K16: 4466 | L16: 3765 | M16: 6713.74 | N16: 6059.54 | O16: 6483.26 | P16: =AVERAGE(N16,O16) -> 6271.4 | Q16: 6030.09 | R16: 6225.82 | S16: 6273.37 | T16: =AVERAGE(Q16,R16,S16) -> 6176.4267 | U16: 6066.75 | V16: 5852.87 | W16: =AVERAGE(U16,V16) -> 5959.81 | X16: 101 | Y16: =X16/100 -> 1.01 | Z16: =Y16*Z15 -> 102.92222 | AA16: 2.9 | AB16: 257 | AC16: 4779.32 | AD16: 655 | AF16: IV 2017 | AG16: 6713.74 | AH16: 1 | AI16: 0 | AJ16: 0 | AK16: 102.92222 | AL16: 2.9 | AM16: 4779.32 | AN16: 6574.007 | AP16: I 2018 | AQ16: 7352.783 | AR16: 1 | AS16: 0 | AT16: 0 | AU16: 103.33391 | AV16: 2.8 | AW16: 4948.06 | AX16: 6713.74
B17: I 2018 | F17: 6448.1392 | G17: 7254.8869 | H17: =AVERAGE(F17,G17) -> 6851.513 | M17: 7352.783 | N17: 6717.461 | O17: 6729.418 | P17: =AVERAGE(N17,O17) -> 6723.4395 | Q17: 6321.151 | R17: 6370.542 | S17: 5970.852 | T17: =AVERAGE(Q17,R17,S17) -> 6220.8483 | U17: 6726.821 | V17: 5774.006 | W17: =AVERAGE(U17,V17) -> 6250.4135 | X17: 100.4 | Y17: =X17/100 -> 1.004 | Z17: =Y17*Z16 -> 103.33391 | AA17: 2.8 | AC17: 4948.06 | AF17: I 2018 | AG17: 7352.783 | AH17: 1 | AI17: 0 | AJ17: 0 | AK17: 103.33391 | AL17: 2.8 | AM17: 4948.06 | AN17: 6713.74 | AP17: II 2018 | AQ17: 7419.03 | AR17: 1 | AS17: 0 | AT17: 0 | AU17: 104.26391 | AV17: 2.6666667 | AW17: 4762.92 | AX17: 7352.783
B18: II 2018 | F18: 6562.8935 | G18: 7543.4766 | H18: =AVERAGE(F18,G18) -> 7053.185 | M18: 7419.03 | N18: 7016.648 | O18: 6992.204 | P18: =AVERAGE(N18,O18) -> 7004.426 | Q18: 6437.304 | R18: 6471.8 | S18: 6645.987 | T18: =AVERAGE(Q18,R18,S18) -> 6518.3637 | U18: 6847.51 | V18: 6186.6 | W18: =AVERAGE(U18,V18) -> 6517.055 | X18: 100.9 | Y18: =X18/100 -> 1.009 | Z18: =Y18*Z17 -> 104.26391 | AA18: 2.6666667 | AC18: 4762.92 | AD18: -75 | AF18: II 2018 | AG18: 7419.03 | AH18: 1 | AI18: 0 | AJ18: 0 | AK18: 104.26391 | AL18: 2.6666667 | AM18: 4762.92 | AN18: 7352.783 | AP18: III 2018 | AQ18: 7530.442 | AR18: 1 | AS18: 0 | AT18: 0 | AU18: 104.15965 | AV18: 2.6 | AW18: 4868.64 | AX18: 7419.03
B19: III 2018 | F19: 7115.27 | G19: 7256.8307 | H19: =AVERAGE(F19,G19) -> 7186.0503 | M19: 7530.442 | N19: 7094.805 | O19: 6973.403 | P19: =AVERAGE(N19,O19) -> 7034.104 | Q19: 6388.13 | R19: 6461.291 | S19: 6535.628 | T19: =AVERAGE(Q19,R19,S19) -> 6461.683 | U19: 6852.366 | V19: 6903.346 | W19: =AVERAGE(U19,V19) -> 6877.856 | X19: 99.9 | Y19: =X19/100 -> 0.999 | Z19: =Y19*Z18 -> 104.15965 | AA19: 2.6 | AC19: 4868.64 | AF19: III 2018 | AG19: 7530.442 | AH19: 1 | AI19: 0 | AJ19: 0 | AK19: 104.15965 | AL19: 2.6 | AM19: 4868.64 | AN19: 7419.03 | AP19: IV 2018 | AQ19: 7725.84 | AR19: 1 | AS19: 0 | AT19: 0 | AU19: 104.57629 | AV19: 2.6 | AW19: 5097.63 | AX19: 7530.442
B20: IV 2018 | F20: 7499.3982 | G20: 7914.5271 | H20: =AVERAGE(F20,G20) -> 7706.9627 | M20: 7725.84 | N20: 7095.77 | O20: 7092.01 | P20: =AVERAGE(N20,O20) -> 7093.89 | Q20: 6793.46 | R20: 6649.29 | S20: 6777.26 | T20: =AVERAGE(Q20,R20,S20) -> 6740.0033 | U20: 7171.48 | V20: 6614.97 | W20: =AVERAGE(U20,V20) -> 6893.225 | X20: 100.4 | Y20: =X20/100 -> 1.004 | Z20: =Y20*Z19 -> 104.57629 | AA20: 2.6 | AC20: 5097.63 | AF20: IV 2018 | AG20: 7725.84 | AH20: 1 | AI20: 0 | AJ20: 0 | AK20: 104.57629 | AL20: 2.6 | AM20: 5097.63 | AN20: 7530.442 | AP20: I 2015 | AQ20: 5428.135 | AR20: 0 | AS20: 1 | AT20: 0 | AU20: 100 | AV20: 5.7333333 | AW20: 4376.77 | AX20: 7725.84
B21: I 2015 | X21: 100.2 | Y21: =X21/100 -> 1.002 | Z21: =Y21*Z20 -> 104.78544 | AF21: I 2015 | AG21: 5428.135 | AH21: 0 | AI21: 1 | AJ21: 0 | AK21: 100 | AL21: 5.7333333 | AM21: 4376.77 | AN21: 7725.84 | AP21: II 2015 | AQ21: 5348.87 | AR21: 0 | AS21: 1 | AT21: 0 | AU21: 100.6 | AV21: 5.3333333 | AW21: 4128.89 | AX21: 5428.135
B22: II 2015 | AF22: II 2015 | AG22: 5348.87 | AH22: 0 | AI22: 1 | AJ22: 0 | AK22: 100.6 | AL22: 5.3333333 | AM22: 4128.89 | AN22: 5428.135 | AP22: III 2015 | AQ22: 5513.615 | AR22: 0 | AS22: 1 | AT22: 0 | AU22: 100.1976 | AV22: 4.6666667 | AW22: 4193.17 | AX22: 5348.87
B23: III 2015 | AF23: III 2015 | AG23: 5513.615 | AH23: 0 | AI23: 1 | AJ23: 0 | AK23: 100.1976 | AL23: 4.6666667 | AM23: 4193.17 | AN23: 5348.87 | AP23: IV 2015 | AQ23: 5451.995 | AR23: 0 | AS23: 1 | AT23: 0 | AU23: 100.0974 | AV23: 4.2 | AW23: 4350 | AX23: 5513.615
B24: IV 2015 | AF24: IV 2015 | AG24: 5451.995 | AH24: 0 | AI24: 1 | AJ24: 0 | AK24: 100.0974 | AL24: 4.2 | AM24: 4350 | AN24: 5513.615 | AP24: I 2016 | AQ24: 5397.72 | AR24: 0 | AS24: 1 | AT24: 0 | AU24: 99.496818 | AV24: 4.1666667 | AW24: 4491.63 | AX24: 5451.995
B25: I 2016 | AF25: I 2016 | AG25: 5397.72 | AH25: 0 | AI25: 1 | AJ25: 0 | AK25: 99.496818 | AL25: 4.1666667 | AM25: 4491.63 | AN25: 5451.995 | AP25: II 2016 | AQ25: 5356.88 | AR25: 0 | AS25: 1 | AT25: 0 | AU25: 100.0938 | AV25: 3.8333333 | AW25: 4333.06 | AX25: 5397.72
B26: II 2016 | AF26: II 2016 | AG26: 5356.88 | AH26: 0 | AI26: 1 | AJ26: 0 | AK26: 100.0938 | AL26: 3.8333333 | AM26: 4333.06 | AN26: 5397.72 | AP26: III 2016 | AQ26: 5451.58 | AR26: 0 | AS26: 1 | AT26: 0 | AU26: 99.993705 | AV26: 3.7333333 | AW26: 4352.28 | AX26: 5356.88
B27: III 2016 | W27: Cena prognozowana | X27: do 35m2 | AF27: III 2016 | AG27: 5451.58 | AH27: 0 | AI27: 1 | AJ27: 0 | AK27: 99.993705 | AL27: 3.7333333 | AM27: 4352.28 | AN27: 5356.88 | AP27: IV 2016 | AQ27: 5607.64 | AR27: 0 | AS27: 1 | AT27: 0 | AU27: 100.69366 | AV27: 3.6333333 | AW27: 4467.88 | AX27: 5451.58
B28: IV 2016 | W28: Gdansk | AF28: IV 2016 | AG28: 5607.64 | AH28: 0 | AI28: 1 | AJ28: 0 | AK28: 100.69366 | AL28: 3.6333333 | AM28: 4467.88 | AN28: 5451.58 | AP28: I 2017 | AQ28: 5775.58 | AR28: 0 | AS28: 1 | AT28: 0 | AU28: 101.7006 | AV28: 3.6 | AW28: 4697.92 | AX28: 5607.64
B29: I 2017 | X29: =-23082+227.77+270.071*104.756+0.272*7725.84 -> 7538.7562 | AF29: I 2017 | AG29: 5775.58 | AH29: 0 | AI29: 1 | AJ29: 0 | AK29: 101.7006 | AL29: 3.6 | AM29: 4697.92 | AN29: 5607.64 | AP29: II 2017 | AQ29: 5911.443 | AR29: 0 | AS29: 1 | AT29: 0 | AU29: 102.1074 | AV29: 3.4 | AW29: 4501.59 | AX29: 5775.58
B30: II 2017 | AF30: II 2017 | AG30: 5911.443 | AH30: 0 | AI30: 1 | AJ30: 0 | AK30: 102.1074 | AL30: 3.4 | AM30: 4501.59 | AN30: 5775.58 | AP30: III 2017 | AQ30: 6077.2615 | AR30: 0 | AS30: 1 | AT30: 0 | AU30: 101.90319 | AV30: 3.2666667 | AW30: 4544.14 | AX30: 5911.443
B31: III 2017 | W31: Wroclaw | AF31: III 2017 | AG31: 6077.2615 | AH31: 0 | AI31: 1 | AJ31: 0 | AK31: 101.90319 | AL31: 3.2666667 | AM31: 4544.14 | AN31: 5911.443 | AP31: IV 2017 | AQ31: 6271.4 | AR31: 0 | AS31: 1 | AT31: 0 | AU31: 102.92222 | AV31: 2.9 | AW31: 4779.32 | AX31: 6077.2615
B32: IV 2017 | X32: =2913.33+253.784+0.498*6984.1 -> 6645.1958 | AF32: IV 2017 | AG32: 6271.4 | AH32: 0 | AI32: 1 | AJ32: 0 | AK32: 102.92222 | AL32: 2.9 | AM32: 4779.32 | AN32: 6077.2615 | AP32: I 2018 | AQ32: 6723.4395 | AR32: 0 | AS32: 1 | AT32: 0 | AU32: 103.33391 | AV32: 2.8 | AW32: 4948.06 | AX32: 6271.4
B33: I 2018 | AF33: I 2018 | AG33: 6723.4395 | AH33: 0 | AI33: 1 | AJ33: 0 | AK33: 103.33391 | AL33: 2.8 | AM33: 4948.06 | AN33: 6271.4 | AP33: II 2018 | AQ33: 7004.426 | AR33: 0 | AS33: 1 | AT33: 0 | AU33: 104.26391 | AV33: 2.6666667 | AW33: 4762.92 | AX33: 6723.4395
B34: II 2018 | W34: Krakow | AF34: II 2018 | AG34: 7004.426 | AH34: 0 | AI34: 1 | AJ34: 0 | AK34: 104.26391 | AL34: 2.6666667 | AM34: 4762.92 | AN34: 6723.4395 | AP34: III 2018 | AQ34: 7034.104 | AR34: 0 | AS34: 1 | AT34: 0 | AU34: 104.15965 | AV34: 2.6 | AW34: 4868.64 | AX34: 7004.426
B35: III 2018 | X35: =3954.406+242.344+0.399*7310.16 -> 7113.5038 | AF35: III 2018 | AG35: 7034.104 | AH35: 0 | AI35: 1 | AJ35: 0 | AK35: 104.15965 | AL35: 2.6 | AM35: 4868.64 | AN35: 7004.426 | AP35: IV 2018 | AQ35: 7093.89 | AR35: 0 | AS35: 1 | AT35: 0 | AU35: 104.57629 | AV35: 2.6 | AW35: 5097.63 | AX35: 7034.104
B36: IV 2018 | AF36: IV 2018 | AG36: 7093.89 | AH36: 0 | AI36: 1 | AJ36: 0 | AK36: 104.57629 | AL36: 2.6 | AM36: 5097.63 | AN36: 7034.104 | AP36: I 2015 | AQ36: 5487.35 | AR36: 0 | AS36: 0 | AT36: 1 | AU36: 100 | AV36: 5.7333333 | AW36: 4376.77 | AX36: 7093.89
B37: I 2015 | W37: Warszawa | AF37: I 2015 | AG37: 5487.35 | AH37: 0 | AI37: 0 | AJ37: 1 | AK37: 100 | AL37: 5.7333333 | AM37: 4376.77 | AN37: 7093.89 | AP37: II 2015 | AQ37: 5490.06 | AR37: 0 | AS37: 0 | AT37: 1 | AU37: 100.6 | AV37: 5.3333333 | AW37: 4128.89 | AX37: 5487.35
B38: II 2015 | X38: =-12221+228.583+178.353*103.949+0.266*8999.6 -> 8941.0926 | AF38: II 2015 | AG38: 5490.06 | AH38: 0 | AI38: 0 | AJ38: 1 | AK38: 100.6 | AL38: 5.3333333 | AM38: 4128.89 | AN38: 5487.35 | AP38: III 2015 | AQ38: 5442.68 | AR38: 0 | AS38: 0 | AT38: 1 | AU38: 100.1976 | AV38: 4.6666667 | AW38: 4193.17 | AX38: 5490.06
B39: III 2015 | AF39: III 2015 | AG39: 5442.68 | AH39: 0 | AI39: 0 | AJ39: 1 | AK39: 100.1976 | AL39: 4.6666667 | AM39: 4193.17 | AN39: 5490.06 | AP39: IV 2015 | AQ39: 5416.5767 | AR39: 0 | AS39: 0 | AT39: 1 | AU39: 100.0974 | AV39: 4.2 | AW39: 4350 | AX39: 5442.68
B40: IV 2015 | AF40: IV 2015 | AG40: 5416.5767 | AH40: 0 | AI40: 0 | AJ40: 1 | AK40: 100.0974 | AL40: 4.2 | AM40: 4350 | AN40: 5442.68 | AP40: I 2016 | AQ40: 5336.2367 | AR40: 0 | AS40: 0 | AT40: 1 | AU40: 99.496818 | AV40: 4.1666667 | AW40: 4491.63 | AX40: 5416.5767
B41: I 2016 | AF41: I 2016 | AG41: 5336.2367 | AH41: 0 | AI41: 0 | AJ41: 1 | AK41: 99.496818 | AL41: 4.1666667 | AM41: 4491.63 | AN41: 5416.5767 | AP41: II 2016 | AQ41: 5248.9067 | AR41: 0 | AS41: 0 | AT41: 1 | AU41: 100.0938 | AV41: 3.8333333 | AW41: 4333.06 | AX41: 5336.2367
...

Sheet Gdansk_2
A1: =Zbiorcza!AF4 -> Kw | B1: =Zbiorcza!AG4 -> Cena | C1: =Zbiorcza!AH4 -> M_do35 | D1: =Zbiorcza!AI4 -> M_35-50 | E1: =Zbiorcza!AJ4 -> M_50-80 | F1: =Zbiorcza!AK4 -> Wsk_cen | G1: =Zbiorcza!AL4 -> Bezr | H1: =Zbiorcza!AM4 -> W
A2: =Zbiorcza!AF5 -> I 2015 | B2: =Zbiorcza!AG5 -> 5730.95 | C2: =Zbiorcza!AH5 -> 1 | D2: =Zbiorcza!AI5 -> 0 | E2: =Zbiorcza!AJ5 -> 0 | F2: =Zbiorcza!AK5 -> 100 | G2: =Zbiorcza!AL5 -> 5.7333333 | H2: =Zbiorcza!AM5 -> 4376.77
A3: =Zbiorcza!AF6 -> II 2015 | B3: =Zbiorcza!AG6 -> 5695.75 | C3: =Zbiorcza!AH6 -> 1 | D3: =Zbiorcza!AI6 -> 0 | E3: =Zbiorcza!AJ6 -> 0 | F3: =Zbiorcza!AK6 -> 100.6 | G3: =Zbiorcza!AL6 -> 5.3333333 | H3: =Zbiorcza!AM6 -> 4128.89
A4: =Zbiorcza!AF7 -> III 2015 | B4: =Zbiorcza!AG7 -> 5617.39 | C4: =Zbiorcza!AH7 -> 1 | D4: =Zbiorcza!AI7 -> 0 | E4: =Zbiorcza!AJ7 -> 0 | F4: =Zbiorcza!AK7 -> 100.1976 | G4: =Zbiorcza!AL7 -> 4.6666667 | H4: =Zbiorcza!AM7 -> 4193.17
A5: =Zbiorcza!AF8 -> IV 2015 | B5: =Zbiorcza!AG8 -> 5564.01 | C5: =Zbiorcza!AH8 -> 1 | D5: =Zbiorcza!AI8 -> 0 | E5: =Zbiorcza!AJ8 -> 0 | F5: =Zbiorcza!AK8 -> 100.0974 | G5: =Zbiorcza!AL8 -> 4.2 | H5: =Zbiorcza!AM8 -> 4350
A6: =Zbiorcza!AF9 -> I 2016 | B6: =Zbiorcza!AG9 -> 5413.68 | C6: =Zbiorcza!AH9 -> 1 | D6: =Zbiorcza!AI9 -> 0 | E6: =Zbiorcza!AJ9 -> 0 | F6: =Zbiorcza!AK9 -> 99.496818 | G6: =Zbiorcza!AL9 -> 4.1666667 | H6: =Zbiorcza!AM9 -> 4491.63
A7: =Zbiorcza!AF10 -> II 2016 | B7: =Zbiorcza!AG10 -> 5517.48 | C7: =Zbiorcza!AH10 -> 1 | D7: =Zbiorcza!AI10 -> 0 | E7: =Zbiorcza!AJ10 -> 0 | F7: =Zbiorcza!AK10 -> 100.0938 | G7: =Zbiorcza!AL10 -> 3.8333333 | H7: =Zbiorcza!AM10 -> 4333.06
A8: =Zbiorcza!AF11 -> III 2016 | B8: =Zbiorcza!AG11 -> 5688.82 | C8: =Zbiorcza!AH11 -> 1 | D8: =Zbiorcza!AI11 -> 0 | E8: =Zbiorcza!AJ11 -> 0 | F8: =Zbiorcza!AK11 -> 99.993705 | G8: =Zbiorcza!AL11 -> 3.7333333 | H8: =Zbiorcza!AM11 -> 4352.28
A9: =Zbiorcza!AF12 -> IV 2016 | B9: =Zbiorcza!AG12 -> 5725.84 | C9: =Zbiorcza!AH12 -> 1 | D9: =Zbiorcza!AI12 -> 0 | E9: =Zbiorcza!AJ12 -> 0 | F9: =Zbiorcza!AK12 -> 100.69366 | G9: =Zbiorcza!AL12 -> 3.6333333 | H9: =Zbiorcza!AM12 -> 4467.88
A10: =Zbiorcza!AF13 -> I 2017 | B10: =Zbiorcza!AG13 -> 6043.25 | C10: =Zbiorcza!AH13 -> 1 | D10: =Zbiorcza!AI13 -> 0 | E10: =Zbiorcza!AJ13 -> 0 | F10: =Zbiorcza!AK13 -> 101.7006 | G10: =Zbiorcza!AL13 -> 3.6 | H10: =Zbiorcza!AM13 -> 4697.92
A11: =Zbiorcza!AF14 -> II 2017 | B11: =Zbiorcza!AG14 -> 6283.44 | C11: =Zbiorcza!AH14 -> 1 | D11: =Zbiorcza!AI14 -> 0 | E11: =Zbiorcza!AJ14 -> 0 | F11: =Zbiorcza!AK14 -> 102.1074 | G11: =Zbiorcza!AL14 -> 3.4 | H11: =Zbiorcza!AM14 -> 4501.59
A12: =Zbiorcza!AF15 -> III 2017 | B12: =Zbiorcza!AG15 -> 6574.007 | C12: =Zbiorcza!AH15 -> 1 | D12: =Zbiorcza!AI15 -> 0 | E12: =Zbiorcza!AJ15 -> 0 | F12: =Zbiorcza!AK15 -> 101.90319 | G12: =Zbiorcza!AL15 -> 3.2666667 | H12: =Zbiorcza!AM15 -> 4544.14
... A65: =Zbiorcza!AF68 -> IV 2018 | B65: =Zbiorcza!AG68 -> 6893.225 | C65: =Zbiorcza!AH68 -> -1 | D65: =Zbiorcza!AI68 -> -1 | E65: =Zbiorcza!AJ68 -> -1 | F65: =Zbiorcza!AK68 -> 104.57629 | G65: =Zbiorcza!AL68 -> 2.6 | H65: =Zbiorcza!AM68 -> 5097.63

Sheet Gdansk_2d
A1: =Zbiorcza!AP4 -> Kw | B1: =Zbiorcza!AQ4 -> Cena | C1: =Zbiorcza!AR4 -> M_do35 | D1: =Zbiorcza!AS4 -> M_35-50 | E1: =Zbiorcza!AT4 -> M_50-80 | F1: =Zbiorcza!AU4 -> Wsk_cen | G1: =Zbiorcza!AV4 -> Bezr | H1: =Zbiorcza!AW4 -> W | I1: =Zbiorcza!AX4 -> cena-1
A2: =Zbiorcza!AP5 -> II 2015 | B2: =Zbiorcza!AQ5 -> 5695.75 | C2: =Zbiorcza!AR5 -> 1 | D2: =Zbiorcza!AS5 -> 0 | E2: =Zbiorcza!AT5 -> 0 | F2: =Zbiorcza!AU5 -> 100.6 | G2: =Zbiorcza!AV5 -> 5.3333333 | H2: =Zbiorcza!AW5 -> 4128.89 | I2: =Zbiorcza!AX5 -> 5730.95
A3: =Zbiorcza!AP6 -> III 2015 | B3: =Zbiorcza!AQ6 -> 5617.39 | C3: =Zbiorcza!AR6 -> 1 | D3: =Zbiorcza!AS6 -> 0 | E3: =Zbiorcza!AT6 -> 0 | F3: =Zbiorcza!AU6 -> 100.1976 | G3: =Zbiorcza!AV6 -> 4.6666667 | H3: =Zbiorcza!AW6 -> 4193.17 | I3: =Zbiorcza!AX6 -> 5695.75
A4: =Zbiorcza!AP7 -> IV 2015 | B4: =Zbiorcza!AQ7 -> 5564.01 | C4: =Zbiorcza!AR7 -> 1 | D4: =Zbiorcza!AS7 -> 0 | E4: =Zbiorcza!AT7 -> 0 | F4: =Zbiorcza!AU7 -> 100.0974 | G4: =Zbiorcza!AV7 -> 4.2 | H4: =Zbiorcza!AW7 -> 4350 | I4: =Zbiorcza!AX7 -> 5617.39
A5: =Zbiorcza!AP8 -> I 2016 | B5: =Zbiorcza!AQ8 -> 5413.68 | C5: =Zbiorcza!AR8 -> 1 | D5: =Zbiorcza!AS8 -> 0 | E5: =Zbiorcza!AT8 -> 0 | F5: =Zbiorcza!AU8 -> 99.496818 | G5: =Zbiorcza!AV8 -> 4.1666667 | H5: =Zbiorcza!AW8 -> 4491.63 | I5: =Zbiorcza!AX8 -> 5564.01
A6: =Zbiorcza!AP9 -> II 2016 | B6: =Zbiorcza!AQ9 -> 5517.48 | C6: =Zbiorcza!AR9 -> 1 | D6: =Zbiorcza!AS9 -> 0 | E6: =Zbiorcza!AT9 -> 0 | F6: =Zbiorcza!AU9 -> 100.0938 | G6: =Zbiorcza!AV9 -> 3.8333333 | H6: =Zbiorcza!AW9 -> 4333.06 | I6: =Zbiorcza!AX9 -> 5413.68
A7: =Zbiorcza!AP10 -> III 2016 | B7: =Zbiorcza!AQ10 -> 5688.82 | C7: =Zbiorcza!AR10 -> 1 | D7: =Zbiorcza!AS10 -> 0 | E7: =Zbiorcza!AT10 -> 0 | F7: =Zbiorcza!AU10 -> 99.993705 | G7: =Zbiorcza!AV10 -> 3.7333333 | H7: =Zbiorcza!AW10 -> 4352.28 | I7: =Zbiorcza!AX10 -> 5517.48
A8: =Zbiorcza!AP11 -> IV 2016 | B8: =Zbiorcza!AQ11 -> 5725.84 | C8: =Zbiorcza!AR11 -> 1 | D8: =Zbiorcza!AS11 -> 0 | E8: =Zbiorcza!AT11 -> 0 | F8: =Zbiorcza!AU11 -> 100.69366 | G8: =Zbiorcza!AV11 -> 3.6333333 | H8: =Zbiorcza!AW11 -> 4467.88 | I8: =Zbiorcza!AX11 -> 5688.82
A9: =Zbiorcza!AP12 -> I 2017 | B9: =Zbiorcza!AQ12 -> 6043.25 | C9: =Zbiorcza!AR12 -> 1 | D9: =Zbiorcza!AS12 -> 0 | E9: =Zbiorcza!AT12 -> 0 | F9: =Zbiorcza!AU12 -> 101.7006 | G9: =Zbiorcza!AV12 -> 3.6 | H9: =Zbiorcza!AW12 -> 4697.92 | I9: =Zbiorcza!AX12 -> 5725.84
A10: =Zbiorcza!AP13 -> II 2017 | B10: =Zbiorcza!AQ13 -> 6283.44 | C10: =Zbiorcza!AR13 -> 1 | D10: =Zbiorcza!AS13 -> 0 | E10: =Zbiorcza!AT13 -> 0 | F10: =Zbiorcza!AU13 -> 102.1074 | G10: =Zbiorcza!AV13 -> 3.4 | H10: =Zbiorcza!AW13 -> 4501.59 | I10: =Zbiorcza!AX13 -> 6043.25
A11: =Zbiorcza!AP14 -> III 2017 | B11: =Zbiorcza!AQ14 -> 6574.007 | C11: =Zbiorcza!AR14 -> 1 | D11: =Zbiorcza!AS14 -> 0 | E11: =Zbiorcza!AT14 -> 0 | F11: =Zbiorcza!AU14 -> 101.90319 | G11: =Zbiorcza!AV14 -> 3.2666667 | H11: =Zbiorcza!AW14 -> 4544.14 | I11: =Zbiorcza!AX14 -> 6283.44
A12: =Zbiorcza!AP15 -> IV 2017 | B12: =Zbiorcza!AQ15 -> 6713.74 | C12: =Zbiorcza!AR15 -> 1 | D12: =Zbiorcza!AS15 -> 0 | E12: =Zbiorcza!AT15 -> 0 | F12: =Zbiorcza!AU15 -> 102.92222 | G12: =Zbiorcza!AV15 -> 2.9 | H12: =Zbiorcza!AW15 -> 4779.32 | I12: =Zbiorcza!AX15 -> 6574.007
... A64: =Zbiorcza!AP67 -> IV 2018 | B64: =Zbiorcza!AQ67 -> 6893.225 | C64: =Zbiorcza!AR67 -> -1 | D64: =Zbiorcza!AS67 -> -1 | E64: =Zbiorcza!AT67 -> -1 | F64: =Zbiorcza!AU67 -> 104.57629 | G64: =Zbiorcza!AV67 -> 2.6 | H64: =Zbiorcza!AW67 -> 5097.63 | I64: =Zbiorcza!AX67 -> 6877.856

Sheet Wroclaw_2
A1: =Zbiorcza!AF72 -> Kw | B1: =Zbiorcza!AG72 -> Cena | C1: =Zbiorcza!AH72 -> M_do35 | D1: =Zbiorcza!AI72 -> M_35-50 | E1: =Zbiorcza!AJ72 -> M_50-80 | F1: =Zbiorcza!AK72 -> Wsk_cen | G1: =Zbiorcza!AL72 -> Bezr | H1: =Zbiorcza!AM72 -> W
A2: =Zbiorcza!AF73 -> I 2015 | B2: =Zbiorcza!AG73 -> 6455.71 | C2: =Zbiorcza!AH73 -> 1 | D2: =Zbiorcza!AI73 -> 0 | E2: =Zbiorcza!AJ73 -> 0 | F2: =Zbiorcza!AK73 -> 100 | G2: =Zbiorcza!AL73 -> 4.1333333 | H2: =Zbiorcza!AM73 -> 4290.73
A3: =Zbiorcza!AF74 -> II 2015 | B3: =Zbiorcza!AG74 -> 5991.98 | C3: =Zbiorcza!AH74 -> 1 | D3: =Zbiorcza!AI74 -> 0 | E3: =Zbiorcza!AJ74 -> 0 | F3: =Zbiorcza!AK74 -> 100.5 | G3: =Zbiorcza!AL74 -> 3.9 | H3: =Zbiorcza!AM74 -> 4230.36
A4: =Zbiorcza!AF75 -> III 2015 | B4: =Zbiorcza!AG75 -> 5760.3 | C4: =Zbiorcza!AH75 -> 1 | D4: =Zbiorcza!AI75 -> 0 | E4: =Zbiorcza!AJ75 -> 0 | F4: =Zbiorcza!AK75 -> 100.1985 | G4: =Zbiorcza!AL75 -> 3.6333333 | H4: =Zbiorcza!AM75 -> 4192.01
A5: =Zbiorcza!AF76 -> IV 2015 | B5: =Zbiorcza!AG76 -> 5686.69 | C5: =Zbiorcza!AH76 -> 1 | D5: =Zbiorcza!AI76 -> 0 | E5: =Zbiorcza!AJ76 -> 0 | F5: =Zbiorcza!AK76 -> 99.797706 | G5: =Zbiorcza!AL76 -> 3.4 | H5: =Zbiorcza!AM76 -> 4417.13
A6: =Zbiorcza!AF77 -> I 2016 | B6: =Zbiorcza!AG77 -> 5845.09 | C6: =Zbiorcza!AH77 -> 1 | D6: =Zbiorcza!AI77 -> 0 | E6: =Zbiorcza!AJ77 -> 0 | F6: =Zbiorcza!AK77 -> 99.099122 | G6: =Zbiorcza!AL77 -> 3.4333333 | H6: =Zbiorcza!AM77 -> 4443.83
A7: =Zbiorcza!AF78 -> II 2016 | B7: =Zbiorcza!AG78 -> 5896.12 | C7: =Zbiorcza!AH78 -> 1 | D7: =Zbiorcza!AI78 -> 0 | E7: =Zbiorcza!AJ78 -> 0 | F7: =Zbiorcza!AK78 -> 99.594618 | G7: =Zbiorcza!AL78 -> 3.2 | H7: =Zbiorcza!AM78 -> 4286.44
A8: =Zbiorcza!AF79 -> III 2016 | B8: =Zbiorcza!AG79 -> 6115.79 | C8: =Zbiorcza!AH79 -> 1 | D8: =Zbiorcza!AI79 -> 0 | E8: =Zbiorcza!AJ79 -> 0 | F8: =Zbiorcza!AK79 -> 99.295834 | G8: =Zbiorcza!AL79 -> 3.0666667 | H8: =Zbiorcza!AM79 -> 4474.43
A9: =Zbiorcza!AF80 -> IV 2016 | B9: =Zbiorcza!AG80 -> 6284.16 | C9: =Zbiorcza!AH80 -> 1 | D9: =Zbiorcza!AI80 -> 0 | E9: =Zbiorcza!AJ80 -> 0 | F9: =Zbiorcza!AK80 -> 99.792313 | G9: =Zbiorcza!AL80 -> 2.8 | H9: =Zbiorcza!AM80 -> 4616.23
A10: =Zbiorcza!AF81 -> I 2017 | B10: =Zbiorcza!AG81 -> 6522.09 | C10: =Zbiorcza!AH81 -> 1 | D10: =Zbiorcza!AI81 -> 0 | E10: =Zbiorcza!AJ81 -> 0 | F10: =Zbiorcza!AK81 -> 101.08961 | G10: =Zbiorcza!AL81 -> 2.7333333 | H10: =Zbiorcza!AM81 -> 4648.69
A11: =Zbiorcza!AF82 -> II 2017 | B11: =Zbiorcza!AG82 -> 6336.619 | C11: =Zbiorcza!AH82 -> 1 | D11: =Zbiorcza!AI82 -> 0 | E11: =Zbiorcza!AJ82 -> 0 | F11: =Zbiorcza!AK82 -> 101.29179 | G11: =Zbiorcza!AL82 -> 2.5666667 | H11: =Zbiorcza!AM82 -> 4657.11
A12: =Zbiorcza!AF83 -> III 2017 | B12: =Zbiorcza!AG83 -> 6149.75 | C12: =Zbiorcza!AH83 -> 1 | D12: =Zbiorcza!AI83 -> 0 | E12: =Zbiorcza!AJ83 -> 0 | F12: =Zbiorcza!AK83 -> 101.08921 | G12: =Zbiorcza!AL83 -> 2.4333333 | H12: =Zbiorcza!AM83 -> 4607.47
... A65: =Zbiorcza!AF136 -> IV 2018 | B65: =Zbiorcza!AG136 -> 5774.635 | C65: =Zbiorcza!AH136 -> -1 | D65: =Zbiorcza!AI136 -> -1 | E65: =Zbiorcza!AJ136 -> -1 | F65: =Zbiorcza!AK136 -> 102.91966 | G65: =Zbiorcza!AL136 -> 1.8333333 | H65: =Zbiorcza!AM136 -> 5245.92

Sheet Wroclaw_2d
A1: =Zbiorcza!AP72 -> Kw | B1: =Zbiorcza!AQ72 -> Cena | C1: =Zbiorcza!AR72 -> M_do35 | D1: =Zbiorcza!AS72 -> M_35-50 | E1: =Zbiorcza!AT72 -> M_50-80 | F1: =Zbiorcza!AU72 -> Wsk_cen | G1: =Zbiorcza!AV72 -> Bezr | H1: =Zbiorcza!AW72 -> W | I1: =Zbiorcza!AX72 -> cena-1
A2: =Zbiorcza!AP73 -> II 2015 | B2: =Zbiorcza!AQ73 -> 5991.98 | C2: =Zbiorcza!AR73 -> 1 | D2: =Zbiorcza!AS73 -> 0 | E2: =Zbiorcza!AT73 -> 0 | F2: =Zbiorcza!AU73 -> 100.5 | G2: =Zbiorcza!AV73 -> 3.9 | H2: =Zbiorcza!AW73 -> 4230.36 | I2: =Zbiorcza!AX73 -> 6455.71
A3: =Zbiorcza!AP74 -> III 2015 | B3: =Zbiorcza!AQ74 -> 5760.3 | C3: =Zbiorcza!AR74 -> 1 | D3: =Zbiorcza!AS74 -> 0 | E3: =Zbiorcza!AT74 -> 0 | F3: =Zbiorcza!AU74 -> 100.1985 | G3: =Zbiorcza!AV74 -> 3.6333333 | H3: =Zbiorcza!AW74 -> 4192.01 | I3: =Zbiorcza!AX74 -> 5991.98
A4: =Zbiorcza!AP75 -> IV 2015 | B4: =Zbiorcza!AQ75 -> 5686.69 | C4: =Zbiorcza!AR75 -> 1 | D4: =Zbiorcza!AS75 -> 0 | E4: =Zbiorcza!AT75 -> 0 | F4: =Zbiorcza!AU75 -> 99.797706 | G4: =Zbiorcza!AV75 -> 3.4 | H4: =Zbiorcza!AW75 -> 4417.13 | I4: =Zbiorcza!AX75 -> 5760.3
A5: =Zbiorcza!AP76 -> I 2016 | B5: =Zbiorcza!AQ76 -> 5845.09 | C5: =Zbiorcza!AR76 -> 1 | D5: =Zbiorcza!AS76 -> 0 | E5: =Zbiorcza!AT76 -> 0 | F5: =Zbiorcza!AU76 -> 99.099122 | G5: =Zbiorcza!AV76 -> 3.4333333 | H5: =Zbiorcza!AW76 -> 4443.83 | I5: =Zbiorcza!AX76 -> 5686.69
A6: =Zbiorcza!AP77 -> II 2016 | B6: =Zbiorcza!AQ77 -> 5896.12 | C6: =Zbiorcza!AR77 -> 1 | D6: =Zbiorcza!AS77 -> 0 | E6: =Zbiorcza!AT77 -> 0 | F6: =Zbiorcza!AU77 -> 99.594618 | G6: =Zbiorcza!AV77 -> 3.2 | H6: =Zbiorcza!AW77 -> 4286.44 | I6: =Zbiorcza!AX77 -> 5845.09
A7: =Zbiorcza!AP78 -> III 2016 | B7: =Zbiorcza!AQ78 -> 6115.79 | C7: =Zbiorcza!AR78 -> 1 | D7: =Zbiorcza!AS78 -> 0 | E7: =Zbiorcza!AT78 -> 0 | F7: =Zbiorcza!AU78 -> 99.295834 | G7: =Zbiorcza!AV78 -> 3.0666667 | H7: =Zbiorcza!AW78 -> 4474.43 | I7: =Zbiorcza!AX78 -> 5896.12
A8: =Zbiorcza!AP79 -> IV 2016 | B8: =Zbiorcza!AQ79 -> 6284.16 | C8: =Zbiorcza!AR79 -> 1 | D8: =Zbiorcza!AS79 -> 0 | E8: =Zbiorcza!AT79 -> 0 | F8: =Zbiorcza!AU79 -> 99.792313 | G8: =Zbiorcza!AV79 -> 2.8 | H8: =Zbiorcza!AW79 -> 4616.23 | I8: =Zbiorcza!AX79 -> 6115.79
A9: =Zbiorcza!AP80 -> I 2017 | B9: =Zbiorcza!AQ80 -> 6522.09 | C9: =Zbiorcza!AR80 -> 1 | D9: =Zbiorcza!AS80 -> 0 | E9: =Zbiorcza!AT80 -> 0 | F9: =Zbiorcza!AU80 -> 101.08961 | G9: =Zbiorcza!AV80 -> 2.7333333 | H9: =Zbiorcza!AW80 -> 4648.69 | I9: =Zbiorcza!AX80 -> 6284.16
A10: =Zbiorcza!AP81 -> II 2017 | B10: =Zbiorcza!AQ81 -> 6336.619 | C10: =Zbiorcza!AR81 -> 1 | D10: =Zbiorcza!AS81 -> 0 | E10: =Zbiorcza!AT81 -> 0 | F10: =Zbiorcza!AU81 -> 101.29179 | G10: =Zbiorcza!AV81 -> 2.5666667 | H10: =Zbiorcza!AW81 -> 4657.11 | I10: =Zbiorcza!AX81 -> 6522.09
A11: =Zbiorcza!AP82 -> III 2017 | B11: =Zbiorcza!AQ82 -> 6149.75 | C11: =Zbiorcza!AR82 -> 1 | D11: =Zbiorcza!AS82 -> 0 | E11: =Zbiorcza!AT82 -> 0 | F11: =Zbiorcza!AU82 -> 101.08921 | G11: =Zbiorcza!AV82 -> 2.4333333 | H11: =Zbiorcza!AW82 -> 4607.47 | I11: =Zbiorcza!AX82 -> 6336.619
A12: =Zbiorcza!AP83 -> IV 2017 | B12: =Zbiorcza!AQ83 -> 6348.97 | C12: =Zbiorcza!AR83 -> 1 | D12: =Zbiorcza!AS83 -> 0 | E12: =Zbiorcza!AT83 -> 0 | F12: =Zbiorcza!AU83 -> 101.99901 | G12: =Zbiorcza!AV83 -> 2.1666667 | H12: =Zbiorcza!AW83 -> 4974.36 | I12: =Zbiorcza!AX83 -> 6149.75
... A64: =Zbiorcza!AP135 -> IV 2018 | B64: =Zbiorcza!AQ135 -> 5774.635 | C64: =Zbiorcza!AR135 -> -1 | D64: =Zbiorcza!AS135 -> -1 | E64: =Zbiorcza!AT135 -> -1 | F64: =Zbiorcza!AU135 -> 102.91966 | G64: =Zbiorcza!AV135 -> 1.8333333 | H64: =Zbiorcza!AW135 -> 5245.92 | I64: =Zbiorcza!AX135 -> 5369.6105

Sheet Krakow_2
A1: =Zbiorcza!AF140 -> Kw | B1: =Zbiorcza!AG140 -> Cena | C1: =Zbiorcza!AH140 -> M_do35 | D1: =Zbiorcza!AI140 -> M_35-50 | E1: =Zbiorcza!AJ140 -> M_50-80 | F1: =Zbiorcza!AK140 -> Wsk_cen | G1: =Zbiorcza!AL140 -> Bezr | H1: =Zbiorcza!AM140 -> W
A2: =Zbiorcza!AF141 -> I 2015 | B2: =Zbiorcza!AG141 -> 6482.78 | C2: =Zbiorcza!AH141 -> 1 | D2: =Zbiorcza!AI141 -> 0 | E2: =Zbiorcza!AJ141 -> 0 | F2: =Zbiorcza!AK141 -> 100 | G2: =Zbiorcza!AL141 -> 5.2 | H2: =Zbiorcza!AM141 -> 4103.62
A3: =Zbiorcza!AF142 -> II 2015 | B3: =Zbiorcza!AG142 -> 6394 | C3: =Zbiorcza!AH142 -> 1 | D3: =Zbiorcza!AI142 -> 0 | E3: =Zbiorcza!AJ142 -> 0 | F3: =Zbiorcza!AK142 -> 100.7 | G3: =Zbiorcza!AL142 -> 4.9 | H3: =Zbiorcza!AM142 -> 3874.54
A4: =Zbiorcza!AF143 -> III 2015 | B4: =Zbiorcza!AG143 -> 6485.21 | C4: =Zbiorcza!AH143 -> 1 | D4: =Zbiorcza!AI143 -> 0 | E4: =Zbiorcza!AJ143 -> 0 | F4: =Zbiorcza!AK143 -> 100.3979 | G4: =Zbiorcza!AL143 -> 4.6333333 | H4: =Zbiorcza!AM143 -> 3938.3
A5: =Zbiorcza!AF144 -> IV 2015 | B5: =Zbiorcza!AG144 -> 6555.298 | C5: =Zbiorcza!AH144 -> 1 | D5: =Zbiorcza!AI144 -> 0 | E5: =Zbiorcza!AJ144 -> 0 | F5: =Zbiorcza!AK144 -> 100.09671 | G5: =Zbiorcza!AL144 -> 4.4666667 | H5: =Zbiorcza!AM144 -> 4160.5
A6: =Zbiorcza!AF145 -> I 2016 | B6: =Zbiorcza!AG145 -> 6697.57 | C6: =Zbiorcza!AH145 -> 1 | D6: =Zbiorcza!AI145 -> 0 | E6: =Zbiorcza!AJ145 -> 0 | F6: =Zbiorcza!AK145 -> 99.596223 | G6: =Zbiorcza!AL145 -> 4.4666667 | H6: =Zbiorcza!AM145 -> 4272.77
A7: =Zbiorcza!AF146 -> II 2016 | B7: =Zbiorcza!AG146 -> 6804.41 | C7: =Zbiorcza!AH146 -> 1 | D7: =Zbiorcza!AI146 -> 0 | E7: =Zbiorcza!AJ146 -> 0 | F7: =Zbiorcza!AK146 -> 100.0942 | G7: =Zbiorcza!AL146 -> 4.2333333 | H7: =Zbiorcza!AM146 -> 4083.58
A8: =Zbiorcza!AF147 -> III 2016 | B8: =Zbiorcza!AG147 -> 6982.324 | C8: =Zbiorcza!AH147 -> 1 | D8: =Zbiorcza!AI147 -> 0 | E8: =Zbiorcza!AJ147 -> 0 | F8: =Zbiorcza!AK147 -> 99.693827 | G8: =Zbiorcza!AL147 -> 3.8666667 | H8: =Zbiorcza!AM147 -> 4145.74
A9: =Zbiorcza!AF148 -> IV 2016 | B9: =Zbiorcza!AG148 -> 6940.39 | C9: =Zbiorcza!AH148 -> 1 | D9: =Zbiorcza!AI148 -> 0 | E9: =Zbiorcza!AJ148 -> 0 | F9: =Zbiorcza!AK148 -> 100.39168 | G9: =Zbiorcza!AL148 -> 3.6333333 | H9: =Zbiorcza!AM148 -> 4212.93
A10: =Zbiorcza!AF149 -> I 2017 | B10: =Zbiorcza!AG149 -> 7185.93 | C10: =Zbiorcza!AH149 -> 1 | D10: =Zbiorcza!AI149 -> 0 | E10: =Zbiorcza!AJ149 -> 0 | F10: =Zbiorcza!AK149 -> 101.59638 | G10: =Zbiorcza!AL149 -> 3.4666667 | H10: =Zbiorcza!AM149 -> 4486.54
A11: =Zbiorcza!AF150 -> II 2017 | B11: =Zbiorcza!AG150 -> 7336.36 | C11: =Zbiorcza!AH150 -> 1 | D11: =Zbiorcza!AI150 -> 0 | E11: =Zbiorcza!AJ150 -> 0 | F11: =Zbiorcza!AK150 -> 101.79958 | G11: =Zbiorcza!AL150 -> 3.2 | H11: =Zbiorcza!AM150 -> 4324.72
A12: =Zbiorcza!AF151 -> III 2017 | B12: =Zbiorcza!AG151 -> 7179.27 | C12: =Zbiorcza!AH151 -> 1 | D12: =Zbiorcza!AI151 -> 0 | E12: =Zbiorcza!AJ151 -> 0 | F12: =Zbiorcza!AK151 -> 101.69778 | G12: =Zbiorcza!AL151 -> 3 | H12: =Zbiorcza!AM151 -> 4415.87
... A65: =Zbiorcza!AF204 -> IV 2018 | B65: =Zbiorcza!AG204 -> 6794.3 | C65: =Zbiorcza!AH204 -> -1 | D65: =Zbiorcza!AI204 -> -1 | E65: =Zbiorcza!AJ204 -> -1 | F65: =Zbiorcza!AK204 -> 104.99066 | G65: =Zbiorcza!AL204 -> 2.4 | H65: =Zbiorcza!AM204 -> 4901.28

Sheet Krakow_2d
A1: =Zbiorcza!AP140 -> Kw | B1: =Zbiorcza!AQ140 -> Cena | C1: =Zbiorcza!AR140 -> M_do35 | D1: =Zbiorcza!AS140 -> M_35-50 | E1: =Zbiorcza!AT140 -> M_50-80 | F1: =Zbiorcza!AU140 -> Wsk_cen | G1: =Zbiorcza!AV140 -> Bezr | H1: =Zbiorcza!AW140 -> W | I1: =Zbiorcza!AX140 -> cena-1
A2: =Zbiorcza!AP141 -> II 2015 | B2: =Zbiorcza!AQ141 -> 6394 | C2: =Zbiorcza!AR141 -> 1 | D2: =Zbiorcza!AS141 -> 0 | E2: =Zbiorcza!AT141 -> 0 | F2: =Zbiorcza!AU141 -> 100.7 | G2: =Zbiorcza!AV141 -> 4.9 | H2: =Zbiorcza!AW141 -> 3874.54 | I2: =Zbiorcza!AX141 -> 6482.78
A3: =Zbiorcza!AP142 -> III 2015 | B3: =Zbiorcza!AQ142 -> 6485.21 | C3: =Zbiorcza!AR142 -> 1 | D3: =Zbiorcza!AS142 -> 0 | E3: =Zbiorcza!AT142 -> 0 | F3: =Zbiorcza!AU142 -> 100.3979 | G3: =Zbiorcza!AV142 -> 4.6333333 | H3: =Zbiorcza!AW142 -> 3938.3 | I3: =Zbiorcza!AX142 -> 6394
A4: =Zbiorcza!AP143 -> IV 2015 | B4: =Zbiorcza!AQ143 -> 6555.298 | C4: =Zbiorcza!AR143 -> 1 | D4: =Zbiorcza!AS143 -> 0 | E4: =Zbiorcza!AT143 -> 0 | F4: =Zbiorcza!AU143 -> 100.09671 | G4: =Zbiorcza!AV143 -> 4.4666667 | H4: =Zbiorcza!AW143 -> 4160.5 | I4: =Zbiorcza!AX143 -> 6485.21
A5: =Zbiorcza!AP144 -> I 2016 | B5: =Zbiorcza!AQ144 -> 6697.57 | C5: =Zbiorcza!AR144 -> 1 | D5: =Zbiorcza!AS144 -> 0 | E5: =Zbiorcza!AT144 -> 0 | F5: =Zbiorcza!AU144 -> 99.596223 | G5: =Zbiorcza!AV144 -> 4.4666667 | H5: =Zbiorcza!AW144 -> 4272.77 | I5: =Zbiorcza!AX144 -> 6555.298
A6: =Zbiorcza!AP145 -> II 2016 | B6: =Zbiorcza!AQ145 -> 6804.41 | C6: =Zbiorcza!AR145 -> 1 | D6: =Zbiorcza!AS145 -> 0 | E6: =Zbiorcza!AT145 -> 0 | F6: =Zbiorcza!AU145 -> 100.0942 | G6: =Zbiorcza!AV145 -> 4.2333333 | H6: =Zbiorcza!AW145 -> 4083.58 | I6: =Zbiorcza!AX145 -> 6697.57
A7: =Zbiorcza!AP146 -> III 2016 | B7: =Zbiorcza!AQ146 -> 6982.324 | C7: =Zbiorcza!AR146 -> 1 | D7: =Zbiorcza!AS146 -> 0 | E7: =Zbiorcza!AT146 -> 0 | F7: =Zbiorcza!AU146 -> 99.693827 | G7: =Zbiorcza!AV146 -> 3.8666667 | H7: =Zbiorcza!AW146 -> 4145.74 | I7: =Zbiorcza!AX146 -> 6804.41
A8: =Zbiorcza!AP147 -> IV 2016 | B8: =Zbiorcza!AQ147 -> 6940.39 | C8: =Zbiorcza!AR147 -> 1 | D8: =Zbiorcza!AS147 -> 0 | E8: =Zbiorcza!AT147 -> 0 | F8: =Zbiorcza!AU147 -> 100.39168 | G8: =Zbiorcza!AV147 -> 3.6333333 | H8: =Zbiorcza!AW147 -> 4212.93 | I8: =Zbiorcza!AX147 -> 6982.324
A9: =Zbiorcza!AP148 -> I 2017 | B9: =Zbiorcza!AQ148 -> 7185.93 | C9: =Zbiorcza!AR148 -> 1 | D9: =Zbiorcza!AS148 -> 0 | E9: =Zbiorcza!AT148 -> 0 | F9: =Zbiorcza!AU148 -> 101.59638 | G9: =Zbiorcza!AV148 -> 3.4666667 | H9: =Zbiorcza!AW148 -> 4486.54 | I9: =Zbiorcza!AX148 -> 6940.39
A10: =Zbiorcza!AP149 -> II 2017 | B10: =Zbiorcza!AQ149 -> 7336.36 | C10: =Zbiorcza!AR149 -> 1 | D10: =Zbiorcza!AS149 -> 0 | E10: =Zbiorcza!AT149 -> 0 | F10: =Zbiorcza!AU149 -> 101.79958 | G10: =Zbiorcza!AV149 -> 3.2 | H10: =Zbiorcza!AW149 -> 4324.72 | I10: =Zbiorcza!AX149 -> 7185.93
A11: =Zbiorcza!AP150 -> III 2017 | B11: =Zbiorcza!AQ150 -> 7179.27 | C11: =Zbiorcza!AR150 -> 1 | D11: =Zbiorcza!AS150 -> 0 | E11: =Zbiorcza!AT150 -> 0 | F11: =Zbiorcza!AU150 -> 101.69778 | G11: =Zbiorcza!AV150 -> 3 | H11: =Zbiorcza!AW150 -> 4415.87 | I11: =Zbiorcza!AX150 -> 7336.36
A12: =Zbiorcza!AP151 -> IV 2017 | B12: =Zbiorcza!AQ151 -> 6811.24 | C12: =Zbiorcza!AR151 -> 1 | D12: =Zbiorcza!AS151 -> 0 | E12: =Zbiorcza!AT151 -> 0 | F12: =Zbiorcza!AU151 -> 103.01985 | G12: =Zbiorcza!AV151 -> 2.7666667 | H12: =Zbiorcza!AW151 -> 4590.72 | I12: =Zbiorcza!AX151 -> 7179.27
... A64: =Zbiorcza!AP203 -> IV 2018 | B64: =Zbiorcza!AQ203 -> 6794.3 | C64: =Zbiorcza!AR203 -> -1 | D64: =Zbiorcza!AS203 -> -1 | E64: =Zbiorcza!AT203 -> -1 | F64: =Zbiorcza!AU203 -> 104.99066 | G64: =Zbiorcza!AV203 -> 2.4 | H64: =Zbiorcza!AW203 -> 4901.28 | I64: =Zbiorcza!AX203 -> 6942.565

Sheet Warszawa_2
A1: =Zbiorcza!AF208 -> Kw | B1: =Zbiorcza!AG208 -> Cena | C1: =Zbiorcza!AH208 -> M_do35 | D1: =Zbiorcza!AI208 -> M_35-50 | E1: =Zbiorcza!AJ208 -> M_50-80 | F1: =Zbiorcza!AK208 -> Wsk_cen | G1: =Zbiorcza!AL208 -> Bezr | H1: =Zbiorcza!AM208 -> W
A2: =Zbiorcza!AF209 -> I 2015 | B2: =Zbiorcza!AG209 -> 7857.91 | C2: =Zbiorcza!AH209 -> 1 | D2: =Zbiorcza!AI209 -> 0 | E2: =Zbiorcza!AJ209 -> 0 | F2: =Zbiorcza!AK209 -> 100 | G2: =Zbiorcza!AL209 -> 4.2333333 | H2: =Zbiorcza!AM209 -> 5267.32
A3: =Zbiorcza!AF210 -> II 2015 | B3: =Zbiorcza!AG210 -> 8284.02 | C3: =Zbiorcza!AH210 -> 1 | D3: =Zbiorcza!AI210 -> 0 | E3: =Zbiorcza!AJ210 -> 0 | F3: =Zbiorcza!AK210 -> 100.5 | G3: =Zbiorcza!AL210 -> 3.9666667 | H3: =Zbiorcza!AM210 -> 5036.68
A4: =Zbiorcza!AF211 -> III 2015 | B4: =Zbiorcza!AG211 -> 8159.41 | C4: =Zbiorcza!AH211 -> 1 | D4: =Zbiorcza!AI211 -> 0 | E4: =Zbiorcza!AJ211 -> 0 | F4: =Zbiorcza!AK211 -> 100.098 | G4: =Zbiorcza!AL211 -> 3.7666667 | H4: =Zbiorcza!AM211 -> 5002.71
A5: =Zbiorcza!AF212 -> IV 2015 | B5: =Zbiorcza!AG212 -> 7800.35 | C5: =Zbiorcza!AH212 -> 1 | D5: =Zbiorcza!AI212 -> 0 | E5: =Zbiorcza!AJ212 -> 0 | F5: =Zbiorcza!AK212 -> 99.897804 | G5: =Zbiorcza!AL212 -> 3.4666667 | H5: =Zbiorcza!AM212 -> 5231.3
A6: =Zbiorcza!AF213 -> I 2016 | B6: =Zbiorcza!AG213 -> 7926.01 | C6: =Zbiorcza!AH213 -> 1 | D6: =Zbiorcza!AI213 -> 0 | E6: =Zbiorcza!AJ213 -> 0 | F6: =Zbiorcza!AK213 -> 99.198519 | G6: =Zbiorcza!AL213 -> 3.3666667 | H6: =Zbiorcza!AM213 -> 5435.95
A7: =Zbiorcza!AF214 -> II 2016 | B7: =Zbiorcza!AG214 -> 8131.97 | C7: =Zbiorcza!AH214 -> 1 | D7: =Zbiorcza!AI214 -> 0 | E7: =Zbiorcza!AJ214 -> 0 | F7: =Zbiorcza!AK214 -> 99.694512 | G7: =Zbiorcza!AL214 -> 3.2 | H7: =Zbiorcza!AM214 -> 5215.26
A8: =Zbiorcza!AF215 -> III 2016 | B8: =Zbiorcza!AG215 -> 8088.39 | C8: =Zbiorcza!AH215 -> 1 | D8: =Zbiorcza!AI215 -> 0 | E8: =Zbiorcza!AJ215 -> 0 | F8: =Zbiorcza!AK215 -> 99.395428 | G8: =Zbiorcza!AL215 -> 3.0333333 | H8: =Zbiorcza!AM215 -> 5147.24
A9: =Zbiorcza!AF216 -> IV 2016 | B9: =Zbiorcza!AG216 -> 8025.11 | C9: =Zbiorcza!AH216 -> 1 | D9: =Zbiorcza!AI216 -> 0 | E9: =Zbiorcza!AJ216 -> 0 | F9: =Zbiorcza!AK216 -> 100.19059 | G9: =Zbiorcza!AL216 -> 2.7666667 | H9: =Zbiorcza!AM216 -> 5403.01
A10: =Zbiorcza!AF217 -> I 2017 | B10: =Zbiorcza!AG217 -> 7829.23 | C10: =Zbiorcza!AH217 -> 1 | D10: =Zbiorcza!AI217 -> 0 | E10: =Zbiorcza!AJ217 -> 0 | F10: =Zbiorcza!AK217 -> 101.1925 | G10: =Zbiorcza!AL217 -> 2.6333333 | H10: =Zbiorcza!AM217 -> 5600.99
A11: =Zbiorcza!AF218 -> II 2017 | B11: =Zbiorcza!AG218 -> 7625.9 | C11: =Zbiorcza!AH218 -> 1 | D11: =Zbiorcza!AI218 -> 0 | E11: =Zbiorcza!AJ218 -> 0 | F11: =Zbiorcza!AK218 -> 101.59727 | G11: =Zbiorcza!AL218 -> 2.4333333 | H11: =Zbiorcza!AM218 -> 5459.95
A12: =Zbiorcza!AF219 -> III 2017 | B12: =Zbiorcza!AG219 -> 7988.82 | C12: =Zbiorcza!AH219 -> 1 | D12: =Zbiorcza!AI219 -> 0 | E12: =Zbiorcza!AJ219 -> 0 | F12: =Zbiorcza!AK219 -> 101.19088 | G12: =Zbiorcza!AL219 -> 2.3 | H12: =Zbiorcza!AM219 -> 5412.94
... A65: =Zbiorcza!AF272 -> IV 2018 | B65: =Zbiorcza!AG272 -> 9161.74 | C65: =Zbiorcza!AH272 -> -1 | D65: =Zbiorcza!AI272 -> -1 | E65: =Zbiorcza!AJ272 -> -1 | F65: =Zbiorcza!AK272 -> 103.74155 | G65: =Zbiorcza!AL272 -> 1.5 | H65: =Zbiorcza!AM272 -> 6131.29

Sheet Warszawa_2d
A1: =Zbiorcza!AP208 -> Kw | B1: =Zbiorcza!AQ208 -> Cena | C1: =Zbiorcza!AR208 -> M_do35 | D1: =Zbiorcza!AS208 -> M_35-50 | E1: =Zbiorcza!AT208 -> M_50-80 | F1: =Zbiorcza!AU208 -> Wsk_cen | G1: =Zbiorcza!AV208 -> Bezr | H1: =Zbiorcza!AW208 -> W | I1: =Zbiorcza!AX208 -> cena-1
A2: =Zbiorcza!AP209 -> II 2015 | B2: =Zbiorcza!AQ209 -> 8284.02 | C2: =Zbiorcza!AR209 -> 1 | D2: =Zbiorcza!AS209 -> 0 | E2: =Zbiorcza!AT209 -> 0 | F2: =Zbiorcza!AU209 -> 100.5 | G2: =Zbiorcza!AV209 -> 3.9666667 | H2: =Zbiorcza!AW209 -> 5036.68 | I2: =Zbiorcza!AX209 -> 7857.91
A3: =Zbiorcza!AP210 -> III 2015 | B3: =Zbiorcza!AQ210 -> 8159.41 | C3: =Zbiorcza!AR210 -> 1 | D3: =Zbiorcza!AS210 -> 0 | E3: =Zbiorcza!AT210 -> 0 | F3: =Zbiorcza!AU210 -> 100.098 | G3: =Zbiorcza!AV210 -> 3.7666667 | H3: =Zbiorcza!AW210 -> 5002.71 | I3: =Zbiorcza!AX210 -> 8284.02
A4: =Zbiorcza!AP211 -> IV 2015 | B4: =Zbiorcza!AQ211 -> 7800.35 | C4: =Zbiorcza!AR211 -> 1 | D4: =Zbiorcza!AS211 -> 0 | E4: =Zbiorcza!AT211 -> 0 | F4: =Zbiorcza!AU211 -> 99.897804 | G4: =Zbiorcza!AV211 -> 3.4666667 | H4: =Zbiorcza!AW211 -> 5231.3 | I4: =Zbiorcza!AX211 -> 8159.41
A5: =Zbiorcza!AP212 -> I 2016 | B5: =Zbiorcza!AQ212 -> 7926.01 | C5: =Zbiorcza!AR212 -> 1 | D5: =Zbiorcza!AS212 -> 0 | E5: =Zbiorcza!AT212 -> 0 | F5: =Zbiorcza!AU212 -> 99.198519 | G5: =Zbiorcza!AV212 -> 3.3666667 | H5: =Zbiorcza!AW212 -> 5435.95 | I5: =Zbiorcza!AX212 -> 7800.35
A6: =Zbiorcza!AP213 -> II 2016 | B6: =Zbiorcza!AQ213 -> 8131.97 | C6: =Zbiorcza!AR213 -> 1 | D6: =Zbiorcza!AS213 -> 0 | E6: =Zbiorcza!AT213 -> 0 | F6: =Zbiorcza!AU213 -> 99.694512 | G6: =Zbiorcza!AV213 -> 3.2 | H6: =Zbiorcza!AW213 -> 5215.26 | I6: =Zbiorcza!AX213 -> 7926.01
A7: =Zbiorcza!AP214 -> III 2016 | B7: =Zbiorcza!AQ214 -> 8088.39 | C7: =Zbiorcza!AR214 -> 1 | D7: =Zbiorcza!AS214 -> 0 | E7: =Zbiorcza!AT214 -> 0 | F7: =Zbiorcza!AU214 -> 99.395428 | G7: =Zbiorcza!AV214 -> 3.0333333 | H7: =Zbiorcza!AW214 -> 5147.24 | I7: =Zbiorcza!AX214 -> 8131.97
A8: =Zbiorcza!AP215 -> IV 2016 | B8: =Zbiorcza!AQ215 -> 8025.11 | C8: =Zbiorcza!AR215 -> 1 | D8: =Zbiorcza!AS215 -> 0 | E8: =Zbiorcza!AT215 -> 0 | F8: =Zbiorcza!AU215 -> 100.19059 | G8: =Zbiorcza!AV215 -> 2.7666667 | H8: =Zbiorcza!AW215 -> 5403.01 | I8: =Zbiorcza!AX215 -> 8088.39
A9: =Zbiorcza!AP216 -> I 2017 | B9: =Zbiorcza!AQ216 -> 7829.23 | C9: =Zbiorcza!AR216 -> 1 | D9: =Zbiorcza!AS216 -> 0 | E9: =Zbiorcza!AT216 -> 0 | F9: =Zbiorcza!AU216 -> 101.1925 | G9: =Zbiorcza!AV216 -> 2.6333333 | H9: =Zbiorcza!AW216 -> 5600.99 | I9: =Zbiorcza!AX216 -> 8025.11
A10: =Zbiorcza!AP217 -> II 2017 | B10: =Zbiorcza!AQ217 -> 7625.9 | C10: =Zbiorcza!AR217 -> 1 | D10: =Zbiorcza!AS217 -> 0 | E10: =Zbiorcza!AT217 -> 0 | F10: =Zbiorcza!AU217 -> 101.59727 | G10: =Zbiorcza!AV217 -> 2.4333333 | H10: =Zbiorcza!AW217 -> 5459.95 | I10: =Zbiorcza!AX217 -> 7829.23
A11: =Zbiorcza!AP218 -> III 2017 | B11: =Zbiorcza!AQ218 -> 7988.82 | C11: =Zbiorcza!AR218 -> 1 | D11: =Zbiorcza!AS218 -> 0 | E11: =Zbiorcza!AT218 -> 0 | F11: =Zbiorcza!AU218 -> 101.19088 | G11: =Zbiorcza!AV218 -> 2.3 | H11: =Zbiorcza!AW218 -> 5412.94 | I11: =Zbiorcza!AX218 -> 7625.9
A12: =Zbiorcza!AP219 -> IV 2017 | B12: =Zbiorcza!AQ219 -> 7865.69 | C12: =Zbiorcza!AR219 -> 1 | D12: =Zbiorcza!AS219 -> 0 | E12: =Zbiorcza!AT219 -> 0 | F12: =Zbiorcza!AU219 -> 102.30398 | G12: =Zbiorcza!AV219 -> 2.0666667 | H12: =Zbiorcza!AW219 -> 5800.4 | I12: =Zbiorcza!AX219 -> 7988.82
... A64: =Zbiorcza!AP271 -> IV 2018 | B64: =Zbiorcza!AQ271 -> 9161.74 | C64: =Zbiorcza!AR271 -> -1 | D64: =Zbiorcza!AS271 -> -1 | E64: =Zbiorcza!AT271 -> -1 | F64: =Zbiorcza!AU271 -> 103.74155 | G64: =Zbiorcza!AV271 -> 1.5 | H64: =Zbiorcza!AW271 -> 6131.29 | I64: =Zbiorcza!AX271 -> 8981.315

Sheet PROGNOZA
B4: Wroclaw
B5: Kowariancja ocen
B6: Zmienna | C6: Intercept | D6: M_do35 | E6: M_50-80 | F6: cena-1
B7: Intercept | C7: 321510.65 | D7: 23674.575 | E7: -14500.5 | F7: -55.024097
B8: M_do35 | C8: 23674.575 | D8: 4409.0242 | E8: -2400.8628 | F8: -4.0567629
B9: M_50-80 | C9: -14500.5 | D9: -2400.8628 | E9: 3236.0943 | F9: 2.4855543
B10: cena-1 | C10: -55.024097 | D10: -4.0567629 | E10: 2.4855543 | F10: 0.0094455563
B12: Krakow
B13: Kowariancja ocen
B14: Zmienna | C14: Intercept | D14: M_do35 | E14: M_35-50 | F14: M_50-80 | G14: cena-1
B15: Intercept | C15: 434208.39 | D15: 21213.66 | E15: -10115.038 | F15: -19364.703 | G15: -66.030971
B16: M_do35 | C16: 21213.66 | D16: 2868.4872 | E16: -1104.8696 | F16: -1556.7667 | G16: -3.2259761
B17: M_35-50 | C17: -10115.038 | D17: -1104.8696 | E17: 1991.399 | F17: -121.30011 | G17: 1.5388368
B18: M_50-80 | C18: -19364.703 | D18: -1556.7667 | E18: -121.30011 | F18: 2619.8304 | G18: 2.9473722
B19: cena-1 | C19: -66.030971 | D19: -3.2259761 | E19: 1.5388368 | F19: 2.9473722 | G19: 0.010055171
B21: Warszawa
B22: Kowariancja ocen
B23: Zmienna | C23: Intercept | D23: M_do35 | E23: M_35-50 | F23: M_50-80 | G23: Wsk_cen | H23: cena-1
B24: Intercept | C24: 4059704.6 | D24: -10859.842 | E24: 14047.673 | F24: 16556.156 | G24: -44300.893 | H24: 53.438056
B25: M_do35 | C25: -10859.842 | D25: 2745.7099 | E25: -1242.2484 | F25: -1320.914 | G25: 238.64043 | H25: -1.6758086
B26: M_35-50 | C26: 14047.673 | D26: -1242.2484 | E26: 2766.3615 | F26: -113.76864 | G26: -288.10468 | H26: 1.9087113
B27: M_50-80 | C27: 16556.156 | D27: -1320.914 | E27: -113.76864 | F27: 2960.8043 | G27: -338.27513 | H27: 2.2334919
B28: Wsk_cen | C28: -44300.893 | D28: 238.64043 | E28: -288.10468 | F28: -338.27513 | G28: 521.44654 | H28: -1.0687783
B29: cena-1 | C29: 53.438056 | D29: -1.6758086 | E29: 1.9087113 | F29: 2.2334919 | G29: -1.0687783 | H29: 0.0069187826
A35: Wroclaw | B35: sigma^2 | C35: 247.57124 | D35: =C35^2 -> 61291.519
B37: X_T^T | C37: 1 | D37: 1 | E37: 0 | F37: 6984.1
B39: X_T | C39: 1
C40: 1
C41: 0
C42: 6984.1
B44: X_T^T*kowari | C44: {=MMULT(C37:F37,C7:F10)} -> -39108.566 | D44: -249.23876 | E44: 457.9971 | F44: 6.88785
B45: X_T^T*kowar*X_T | C45: =MMULT(C44:F44,C39:C42) -> 8747.6282
B46: X_T^T*kowar*X_T+sigma^2 | C46: =C45+D35 -> 70039.147
B47: pierw | C47: =SQRT(C46) -> 264.6491
A49: Warszawa | B49: sigma^2 | C49: 217.98087 | D49: =C49^2 -> 47515.66
B51: X_T^T | C51: 1 | D51: 1 | E51: 0 | F51: 0 | G51: 103.949 | H51: 8999.6
B53: X_T | C53: 1
C54: 1
C55: 0
C56: 0
...
